<?xml version="1.0" ?>
<!-- =================================================================================== -->
<!-- |    This document was autogenerated by xacro from src/HARP2/robot_description/urdf/robot.urdf.xacro | -->
<!-- |    EDITING THIS FILE BY HAND IS NOT RECOMMENDED                                 | -->
<!-- =================================================================================== -->
<robot name="robot">
  <!-- Specify some standard inertial calculations https://en.wikipedia.org/wiki/List_of_moments_of_inertia -->
  <!-- These make use of xacro's mathematical functionality -->
  <!-- Specify some standard inertial calculations https://en.wikipedia.org/wiki/List_of_moments_of_inertia -->
  <!-- These make use of xacro's mathematical functionality -->
  <ros2_control name="GazeboSystem" type="system">
    <hardware>
      <plugin>gazebo_ros2_control/GazeboSystem</plugin>
    </hardware>
    <joint name="joint_wheel_roueholonome1">
      <command_interface name="velocity">
        <param name="min">-10</param>
        <param name="max">10</param>
      </command_interface>
      <state_interface name="position"/>
      <state_interface name="velocity"/>
    </joint>
    <joint name="joint_wheel_roueholonome2">
      <command_interface name="velocity">
        <param name="min">-10</param>
        <param name="max">10</param>
      </command_interface>
      <state_interface name="position"/>
      <state_interface name="velocity"/>
    </joint>
    <joint name="joint_wheel_roueholonome3">
      <command_interface name="velocity">
        <param name="min">-10</param>
        <param name="max">10</param>
      </command_interface>
      <state_interface name="position"/>
      <state_interface name="velocity"/>
    </joint>
  </ros2_control>
  <!-- This first link called "base_footprint" is empty -->
  <link name="base_footprint"/>
  <joint name="base_joint" type="fixed">
    <origin rpy="0 0 0" xyz="0 0 -0.01"/>
    <parent link="base_link"/>
    <child link="base_footprint"/>
  </joint>
  <link name="base_link">
    <visual>
      <origin rpy="0 0 0" xyz="0 0 0"/>
      <geometry>
        <mesh filename="file:///home/floris/ros2_ws/install/robot_description/share/robot_description/urdf/robot_base.stl"/>
      </geometry>
      <material name="robot_base_material">
        <color rgba="1 1 1 1.0"/>
      </material>
    </visual>
    <collision>
      <origin rpy="0 0 0" xyz="0 0 0"/>
      <geometry>
        <mesh filename="file:///home/floris/ros2_ws/install/robot_description/share/robot_description/urdf/robot_base.stl"/>
      </geometry>
      <surface>
        <contact>
          <ode>
            <min_depth>0.001</min_depth>
          </ode>
        </contact>
      </surface>
    </collision>
    <inertial>
      <origin rpy="0 0 0" xyz="0 0 0.005"/>
      <mass value="3.0"/>
      <inertia ixx="0.024325000000000003" ixy="0.0" ixz="0.0" iyy="0.024325000000000003" iyz="0.0" izz="0.0486"/>
    </inertial>
  </link>
  <gazebo reference="base_link">
    <!-- <material>Gazebo/Black</material> -->
    <mu1>1.0</mu1>
    <mu2>0.8</mu2>
    <kp>500000.0</kp>
    <kd>10.0</kd>
    <min_depth>0.1</min_depth>
    <maxVel>0.1</maxVel>
  </gazebo>
  <link name="roueholonome1">
    <visual>
      <origin rpy="1.570796326794896558 1.570796326794896558 0" xyz="0 0 0"/>
      <geometry>
        <mesh filename="file:///home/floris/ros2_ws/install/robot_description/share/robot_description/urdf/holonomic_wheel/roueholonome.stl"/>
      </geometry>
      <material name="roueholonome_material">
        <color rgba="0.80000000000000004441 0.80000000000000004441 0.80000000000000004441 1.0"/>
      </material>
    </visual>
    <collision>
      <origin rpy="1.570796326794896558 1.570796326794896558 0" xyz="0 0 0"/>
      <geometry>
        <mesh filename="file:///home/floris/ros2_ws/install/robot_description/share/robot_description/urdf/holonomic_wheel/roueholonome.stl"/>
      </geometry>
    </collision>
    <inertial>
      <origin rpy="0 0 0" xyz="-2.5184848675754577033e-17 4.8001766176252168599e-18 -0.0090500000000000198341"/>
      <mass value="0.073"/>
      <inertia ixx="1.923702083333333e-05" ixy="0.0" ixz="0.0" iyy="1.923702083333333e-05" iyz="0.0" izz="3.285e-05"/>
    </inertial>
  </link>
  <gazebo reference="roueholonome1">
    <material>Gazebo/Grey</material>
    <mu1>100.0</mu1>
    <mu2>100.8</mu2>
    <kp>500000.0</kp>
    <kd>10.0</kd>
    <min_depth>0.1</min_depth>
    <maxVel>0.1</maxVel>
  </gazebo>
  <link name="rouleau_1_roueholonome1">
    <visual>
      <origin rpy="-1.570796326794896558 7.4458241183643537248e-17 -2.2931001679521526839e-18" xyz="0 -6.9388939039072283776e-18 -1.3660947373317355868e-17"/>
      <geometry>
        <mesh filename="file:///home/floris/ros2_ws/install/robot_description/share/robot_description/urdf/holonomic_wheel/rouleau.stl"/>
      </geometry>
      <material name="rouleau_material">
        <color rgba="0.16078431372549020772 0.16078431372549020772 0.16078431372549020772 1.0"/>
      </material>
    </visual>
    <collision>
      <origin rpy="-1.570796326794896558 7.4458241183643537248e-17 -2.2931001679521526839e-18" xyz="0 -6.9388939039072283776e-18 -1.3660947373317355868e-17"/>
      <geometry>
        <mesh filename="file:///home/floris/ros2_ws/install/robot_description/share/robot_description/urdf/holonomic_wheel/rouleau.stl"/>
      </geometry>
    </collision>
    <inertial>
      <origin rpy="0 0 0" xyz="-1.3533020587659002873e-19 -6.9388939039072283776e-18 -7.6373245842409416038e-17"/>
      <mass value="0.01"/>
      <inertia ixx="4.4145833333333327e-07" ixy="0.0" ixz="0.0" iyy="4.4145833333333327e-07" iyz="0.0" izz="2.8125e-07"/>
    </inertial>
  </link>
  <gazebo reference="rouleau_1_roueholonome1">
    <material>Gazebo/Black</material>
    <mu1>100.0</mu1>
    <mu2>100.8</mu2>
    <kp>500000.0</kp>
    <kd>10.0</kd>
    <min_depth>0.1</min_depth>
    <maxVel>0.1</maxVel>
  </gazebo>
  <joint name="Rouleau_a_roueholonome1" type="continuous">
    <origin rpy="-0.62831853071795829013 1.570796326794896558 0" xyz="-0.013107611126122130016 0.018041078974561301773 -0.015600000000000002753"/>
    <parent link="roueholonome1"/>
    <child link="rouleau_1_roueholonome1"/>
    <axis xyz="0 0 1"/>
    <limit effort="1" velocity="20"/>
    <joint_properties friction="10000.0"/>
  </joint>
  <link name="rouleau_2_roueholonome1">
    <visual>
      <origin rpy="-1.570796326794896558 1.704115477206629922e-17 1.0069492273628905161e-16" xyz="0 3.4694469519536141888e-18 -3.4694469519536141888e-18"/>
      <geometry>
        <mesh filename="file:///home/floris/ros2_ws/install/robot_description/share/robot_description/urdf/holonomic_wheel/rouleau.stl"/>
      </geometry>
      <material name="rouleau_material">
        <color rgba="0.16078431372549020772 0.16078431372549020772 0.16078431372549020772 1.0"/>
      </material>
    </visual>
    <collision>
      <origin rpy="-1.570796326794896558 1.704115477206629922e-17 1.0069492273628905161e-16" xyz="0 3.4694469519536141888e-18 -3.4694469519536141888e-18"/>
      <geometry>
        <mesh filename="file:///home/floris/ros2_ws/install/robot_description/share/robot_description/urdf/holonomic_wheel/rouleau.stl"/>
      </geometry>
    </collision>
    <inertial>
      <origin rpy="0 0 0" xyz="-1.3533020587657876204e-19 3.4694469519536203518e-18 -6.6181745421045662032e-17"/>
      <mass value="0.01"/>
      <inertia ixx="4.4145833333333327e-07" ixy="0.0" ixz="0.0" iyy="4.4145833333333327e-07" iyz="0.0" izz="2.8125e-07"/>
    </inertial>
  </link>
  <gazebo reference="rouleau_2_roueholonome1">
    <material>Gazebo/Black</material>
    <mu1>100.0</mu1>
    <mu2>100.8</mu2>
    <kp>500000.0</kp>
    <kd>10.0</kd>
    <min_depth>0.1</min_depth>
    <maxVel>0.1</maxVel>
  </gazebo>
  <joint name="Rouleau_b_roueholonome1" type="continuous">
    <origin rpy="-1.8849555921538763137 1.570796326794896558 0" xyz="-0.02120856031338196751 -0.0068910789745613692386 -0.015599999999999974998"/>
    <parent link="roueholonome1"/>
    <child link="rouleau_2_roueholonome1"/>
    <axis xyz="0 0 1"/>
    <limit effort="1" velocity="20"/>
    <joint_properties friction="10000.0"/>
  </joint>
  <link name="rouleau_3_roueholonome1">
    <visual>
      <origin rpy="-1.57079632679489678 -3.8858620800219972321e-17 1.4515871623615415173e-17" xyz="-2.7755575615628913511e-17 -5.2041704279304212832e-18 3.4694469519536141888e-18"/>
      <geometry>
        <mesh filename="file:///home/floris/ros2_ws/install/robot_description/share/robot_description/urdf/holonomic_wheel/rouleau.stl"/>
      </geometry>
      <material name="rouleau_material">
        <color rgba="0.16078431372549020772 0.16078431372549020772 0.16078431372549020772 1.0"/>
      </material>
    </visual>
    <collision>
      <origin rpy="-1.57079632679489678 -3.8858620800219972321e-17 1.4515871623615415173e-17" xyz="-2.7755575615628913511e-17 -5.2041704279304212832e-18 3.4694469519536141888e-18"/>
      <geometry>
        <mesh filename="file:///home/floris/ros2_ws/install/robot_description/share/robot_description/urdf/holonomic_wheel/rouleau.stl"/>
      </geometry>
    </collision>
    <inertial>
      <origin rpy="0 0 0" xyz="-2.7890905821505490852e-17 -5.2041704279304320684e-18 -5.9242851517138445981e-17"/>
      <mass value="0.01"/>
      <inertia ixx="4.4145833333333327e-07" ixy="0.0" ixz="0.0" iyy="4.4145833333333327e-07" iyz="0.0" izz="2.8125e-07"/>
    </inertial>
  </link>
  <gazebo reference="rouleau_3_roueholonome1">
    <material>Gazebo/Black</material>
    <mu1>100.0</mu1>
    <mu2>100.8</mu2>
    <kp>500000.0</kp>
    <kd>10.0</kd>
    <min_depth>0.1</min_depth>
    <maxVel>0.1</maxVel>
  </gazebo>
  <joint name="Rouleau_c_roueholonome1" type="continuous">
    <origin rpy="2.2204460492503130808e-16 1.570796326794896558 0" xyz="-6.9388939039072283776e-18 -0.022300000000000003847 -0.015600000000000002753"/>
    <parent link="roueholonome1"/>
    <child link="rouleau_3_roueholonome1"/>
    <axis xyz="0 0 1"/>
    <limit effort="1" velocity="20"/>
    <joint_properties friction="10000.0"/>
  </joint>
  <link name="rouleau_4_roueholonome1">
    <visual>
      <origin rpy="-1.57079632679489678 2.2968870007964204446e-18 -1.2816475377239519703e-17" xyz="0 -5.2041704279304212832e-18 6.9388939039072283776e-18"/>
      <geometry>
        <mesh filename="file:///home/floris/ros2_ws/install/robot_description/share/robot_description/urdf/holonomic_wheel/rouleau.stl"/>
      </geometry>
      <material name="rouleau_material">
        <color rgba="0.16078431372549020772 0.16078431372549020772 0.16078431372549020772 1.0"/>
      </material>
    </visual>
    <collision>
      <origin rpy="-1.57079632679489678 2.2968870007964204446e-18 -1.2816475377239519703e-17" xyz="0 -5.2041704279304212832e-18 6.9388939039072283776e-18"/>
      <geometry>
        <mesh filename="file:///home/floris/ros2_ws/install/robot_description/share/robot_description/urdf/holonomic_wheel/rouleau.stl"/>
      </geometry>
    </collision>
    <inertial>
      <origin rpy="0 0 0" xyz="-1.3533020587658461205e-19 -5.2041704279304251351e-18 -5.5773404565184819466e-17"/>
      <mass value="0.01"/>
      <inertia ixx="4.4145833333333327e-07" ixy="0.0" ixz="0.0" iyy="4.4145833333333327e-07" iyz="0.0" izz="2.8125e-07"/>
    </inertial>
  </link>
  <gazebo reference="rouleau_4_roueholonome1">
    <material>Gazebo/Black</material>
    <mu1>100.0</mu1>
    <mu2>100.8</mu2>
    <kp>500000.0</kp>
    <kd>10.0</kd>
    <min_depth>0.1</min_depth>
    <maxVel>0.1</maxVel>
  </gazebo>
  <joint name="Rouleau_d_roueholonome1" type="continuous">
    <origin rpy="-1.2566370614359168023 1.570796326794896558 0" xyz="0.021208560313381925877 -0.006891078974561298115 -0.015600000000000002753"/>
    <parent link="roueholonome1"/>
    <child link="rouleau_4_roueholonome1"/>
    <axis xyz="0 0 1"/>
    <limit effort="1" velocity="20"/>
    <joint_properties friction="10000.0"/>
  </joint>
  <link name="rouleau_5_roueholonome1">
    <visual>
      <origin rpy="-1.570796326794896558 -3.1610276974795425021e-18 9.1157131572497391962e-18" xyz="-2.7755575615628913511e-17 3.4694469519536141888e-18 3.4694469519536141888e-18"/>
      <geometry>
        <mesh filename="file:///home/floris/ros2_ws/install/robot_description/share/robot_description/urdf/holonomic_wheel/rouleau.stl"/>
      </geometry>
      <material name="rouleau_material">
        <color rgba="0.16078431372549020772 0.16078431372549020772 0.16078431372549020772 1.0"/>
      </material>
    </visual>
    <collision>
      <origin rpy="-1.570796326794896558 -3.1610276974795425021e-18 9.1157131572497391962e-18" xyz="-2.7755575615628913511e-17 3.4694469519536141888e-18 3.4694469519536141888e-18"/>
      <geometry>
        <mesh filename="file:///home/floris/ros2_ws/install/robot_description/share/robot_description/urdf/holonomic_wheel/rouleau.stl"/>
      </geometry>
    </collision>
    <inertial>
      <origin rpy="0 0 0" xyz="-2.7890905821505497015e-17 3.4694469519536134185e-18 -5.9242851517138445981e-17"/>
      <mass value="0.01"/>
      <inertia ixx="4.4145833333333327e-07" ixy="0.0" ixz="0.0" iyy="4.4145833333333327e-07" iyz="0.0" izz="2.8125e-07"/>
    </inertial>
  </link>
  <gazebo reference="rouleau_5_roueholonome1">
    <material>Gazebo/Black</material>
    <mu1>100.0</mu1>
    <mu2>100.8</mu2>
    <kp>500000.0</kp>
    <kd>10.0</kd>
    <min_depth>0.1</min_depth>
    <maxVel>0.1</maxVel>
  </gazebo>
  <joint name="Rouleau_e_roueholonome1" type="continuous">
    <origin rpy="0.62831853071795817911 1.570796326794896558 0" xyz="0.013107611126122100526 0.018041078974561364223 -0.015600000000000002753"/>
    <parent link="roueholonome1"/>
    <child link="rouleau_5_roueholonome1"/>
    <axis xyz="0 0 1"/>
    <limit effort="1" velocity="20"/>
    <joint_properties friction="10000.0"/>
  </joint>
  <link name="rouleau_6_roueholonome1">
    <visual>
      <origin rpy="-1.57079632679489678 -3.8858615837136297003e-17 1.4515871623615415173e-17" xyz="0 0 5.2041704279304212832e-18"/>
      <geometry>
        <mesh filename="file:///home/floris/ros2_ws/install/robot_description/share/robot_description/urdf/holonomic_wheel/rouleau.stl"/>
      </geometry>
      <material name="rouleau_material">
        <color rgba="0.16078431372549020772 0.16078431372549020772 0.16078431372549020772 1.0"/>
      </material>
    </visual>
    <collision>
      <origin rpy="-1.57079632679489678 -3.8858615837136297003e-17 1.4515871623615415173e-17" xyz="0 0 5.2041704279304212832e-18"/>
      <geometry>
        <mesh filename="file:///home/floris/ros2_ws/install/robot_description/share/robot_description/urdf/holonomic_wheel/rouleau.stl"/>
      </geometry>
    </collision>
    <inertial>
      <origin rpy="0 0 0" xyz="-1.3533020587657560833e-19 -4.0005310894682744636e-33 -5.7508128041161638886e-17"/>
      <mass value="0.01"/>
      <inertia ixx="4.4145833333333327e-07" ixy="0.0" ixz="0.0" iyy="4.4145833333333327e-07" iyz="0.0" izz="2.8125e-07"/>
    </inertial>
  </link>
  <gazebo reference="rouleau_6_roueholonome1">
    <material>Gazebo/Black</material>
    <mu1>100.0</mu1>
    <mu2>100.8</mu2>
    <kp>500000.0</kp>
    <kd>10.0</kd>
    <min_depth>0.1</min_depth>
    <maxVel>0.1</maxVel>
  </gazebo>
  <joint name="Rouleau_f_roueholonome1" type="continuous">
    <origin rpy="-0 1.570796326794896558 0" xyz="-8.6736173798840354721e-18 0.022299999999999993439 -0.0025000000000000022204"/>
    <parent link="roueholonome1"/>
    <child link="rouleau_6_roueholonome1"/>
    <axis xyz="0 0 1"/>
    <limit effort="1" velocity="20"/>
    <joint_properties friction="10000.0"/>
  </joint>
  <link name="rouleau_7_roueholonome1">
    <visual>
      <origin rpy="-1.57079632679489678 2.2968870007964204446e-18 -1.2816475377239519703e-17" xyz="0 -6.9388939039072283776e-18 5.2041704279304212832e-18"/>
      <geometry>
        <mesh filename="file:///home/floris/ros2_ws/install/robot_description/share/robot_description/urdf/holonomic_wheel/rouleau.stl"/>
      </geometry>
      <material name="rouleau_material">
        <color rgba="0.16078431372549020772 0.16078431372549020772 0.16078431372549020772 1.0"/>
      </material>
    </visual>
    <collision>
      <origin rpy="-1.57079632679489678 2.2968870007964204446e-18 -1.2816475377239519703e-17" xyz="0 -6.9388939039072283776e-18 5.2041704279304212832e-18"/>
      <geometry>
        <mesh filename="file:///home/floris/ros2_ws/install/robot_description/share/robot_description/urdf/holonomic_wheel/rouleau.stl"/>
      </geometry>
    </collision>
    <inertial>
      <origin rpy="0 0 0" xyz="-1.3533020587658461205e-19 -6.9388939039072329999e-18 -5.750812804116162656e-17"/>
      <mass value="0.01"/>
      <inertia ixx="4.4145833333333327e-07" ixy="0.0" ixz="0.0" iyy="4.4145833333333327e-07" iyz="0.0" izz="2.8125e-07"/>
    </inertial>
  </link>
  <gazebo reference="rouleau_7_roueholonome1">
    <material>Gazebo/Black</material>
    <mu1>100.0</mu1>
    <mu2>100.8</mu2>
    <kp>500000.0</kp>
    <kd>10.0</kd>
    <min_depth>0.1</min_depth>
    <maxVel>0.1</maxVel>
  </gazebo>
  <joint name="Rouleau_g_roueholonome1" type="continuous">
    <origin rpy="-1.2566370614359168023 1.570796326794896558 0" xyz="-0.021208560313381932816 0.0068910789745613033191 -0.0025000000000000022204"/>
    <parent link="roueholonome1"/>
    <child link="rouleau_7_roueholonome1"/>
    <axis xyz="0 0 1"/>
    <limit effort="1" velocity="20"/>
    <joint_properties friction="10000.0"/>
  </joint>
  <link name="rouleau_8_roueholonome1">
    <visual>
      <origin rpy="-1.570796326794896558 -3.1610276974795425021e-18 9.1157131572497391962e-18" xyz="0 -1.0408340855860842566e-17 -3.4694469519536141888e-18"/>
      <geometry>
        <mesh filename="file:///home/floris/ros2_ws/install/robot_description/share/robot_description/urdf/holonomic_wheel/rouleau.stl"/>
      </geometry>
      <material name="rouleau_material">
        <color rgba="0.16078431372549020772 0.16078431372549020772 0.16078431372549020772 1.0"/>
      </material>
    </visual>
    <collision>
      <origin rpy="-1.570796326794896558 -3.1610276974795425021e-18 9.1157131572497391962e-18" xyz="0 -1.0408340855860842566e-17 -3.4694469519536141888e-18"/>
      <geometry>
        <mesh filename="file:///home/floris/ros2_ws/install/robot_description/share/robot_description/urdf/holonomic_wheel/rouleau.stl"/>
      </geometry>
    </collision>
    <inertial>
      <origin rpy="0 0 0" xyz="-1.3533020587658068797e-19 -1.0408340855860842566e-17 -6.6181745421045674358e-17"/>
      <mass value="0.01"/>
      <inertia ixx="4.4145833333333327e-07" ixy="0.0" ixz="0.0" iyy="4.4145833333333327e-07" iyz="0.0" izz="2.8125e-07"/>
    </inertial>
  </link>
  <gazebo reference="rouleau_8_roueholonome1">
    <material>Gazebo/Black</material>
    <mu1>100.0</mu1>
    <mu2>100.8</mu2>
    <kp>500000.0</kp>
    <kd>10.0</kd>
    <min_depth>0.1</min_depth>
    <maxVel>0.1</maxVel>
  </gazebo>
  <joint name="Rouleau_h_roueholonome1" type="continuous">
    <origin rpy="0.62831853071795817911 1.570796326794896558 0" xyz="-0.013107611126122147363 -0.018041078974561343407 -0.0024999999999999744649"/>
    <parent link="roueholonome1"/>
    <child link="rouleau_8_roueholonome1"/>
    <axis xyz="0 0 1"/>
    <limit effort="1" velocity="20"/>
    <joint_properties friction="10000.0"/>
  </joint>
  <link name="rouleau_9_roueholonome1">
    <visual>
      <origin rpy="-1.570796326794896558 7.4458252970967266128e-17 -2.2931034766746028961e-18" xyz="0 0 -2.4936649967166601982e-18"/>
      <geometry>
        <mesh filename="file:///home/floris/ros2_ws/install/robot_description/share/robot_description/urdf/holonomic_wheel/rouleau.stl"/>
      </geometry>
      <material name="rouleau_material">
        <color rgba="0.16078431372549020772 0.16078431372549020772 0.16078431372549020772 1.0"/>
      </material>
    </visual>
    <collision>
      <origin rpy="-1.570796326794896558 7.4458252970967266128e-17 -2.2931034766746028961e-18" xyz="0 0 -2.4936649967166601982e-18"/>
      <geometry>
        <mesh filename="file:///home/floris/ros2_ws/install/robot_description/share/robot_description/urdf/holonomic_wheel/rouleau.stl"/>
      </geometry>
    </collision>
    <inertial>
      <origin rpy="0 0 0" xyz="-1.353302058765900528e-19 -8.1870457482636967244e-35 -6.5205963465808720368e-17"/>
      <mass value="0.01"/>
      <inertia ixx="4.4145833333333327e-07" ixy="0.0" ixz="0.0" iyy="4.4145833333333327e-07" iyz="0.0" izz="2.8125e-07"/>
    </inertial>
  </link>
  <gazebo reference="rouleau_9_roueholonome1">
    <material>Gazebo/Black</material>
    <mu1>100.0</mu1>
    <mu2>100.8</mu2>
    <kp>500000.0</kp>
    <kd>10.0</kd>
    <min_depth>0.1</min_depth>
    <maxVel>0.1</maxVel>
  </gazebo>
  <joint name="Rouleau_i_roueholonome1" type="continuous">
    <origin rpy="-0.62831853071795884524 1.570796326794896558 0" xyz="0.013107611126122112669 -0.018041078974561298304 -0.0025000000000000022204"/>
    <parent link="roueholonome1"/>
    <child link="rouleau_9_roueholonome1"/>
    <axis xyz="0 0 1"/>
    <limit effort="1" velocity="20"/>
    <joint_properties friction="10000.0"/>
  </joint>
  <link name="rouleau_10_roueholonome1">
    <visual>
      <origin rpy="-1.570796326794896558 1.704115477206629922e-17 1.0069492273628905161e-16" xyz="0 0 3.4694469519536141888e-18"/>
      <geometry>
        <mesh filename="file:///home/floris/ros2_ws/install/robot_description/share/robot_description/urdf/holonomic_wheel/rouleau.stl"/>
      </geometry>
      <material name="rouleau_material">
        <color rgba="0.16078431372549020772 0.16078431372549020772 0.16078431372549020772 1.0"/>
      </material>
    </visual>
    <collision>
      <origin rpy="-1.570796326794896558 1.704115477206629922e-17 1.0069492273628905161e-16" xyz="0 0 3.4694469519536141888e-18"/>
      <geometry>
        <mesh filename="file:///home/floris/ros2_ws/install/robot_description/share/robot_description/urdf/holonomic_wheel/rouleau.stl"/>
      </geometry>
    </collision>
    <inertial>
      <origin rpy="0 0 0" xyz="-1.3533020587657876204e-19 6.4315019349350432793e-33 -5.9242851517138433655e-17"/>
      <mass value="0.01"/>
      <inertia ixx="4.4145833333333327e-07" ixy="0.0" ixz="0.0" iyy="4.4145833333333327e-07" iyz="0.0" izz="2.8125e-07"/>
    </inertial>
  </link>
  <gazebo reference="rouleau_10_roueholonome1">
    <material>Gazebo/Black</material>
    <mu1>100.0</mu1>
    <mu2>100.8</mu2>
    <kp>500000.0</kp>
    <kd>10.0</kd>
    <min_depth>0.1</min_depth>
    <maxVel>0.1</maxVel>
  </gazebo>
  <joint name="Rouleau_j_roueholonome1" type="continuous">
    <origin rpy="-1.8849555921538763137 1.570796326794896558 0" xyz="0.021208560313381953633 0.0068910789745613831164 -0.0025000000000000022204"/>
    <parent link="roueholonome1"/>
    <child link="rouleau_10_roueholonome1"/>
    <axis xyz="0 0 1"/>
    <limit effort="1" velocity="20"/>
    <joint_properties friction="10000.0"/>
  </joint>
  <joint name="joint_wheel_roueholonome1" type="continuous">
    <origin rpy="1.5707963059327449962 -3.6134307765750467638e-08 -1.0471975663321160255" xyz="0.11539788567280147291 0.066624999269165083304 0.018159998763917353098"/>
    <parent link="base_link"/>
    <child link="roueholonome1"/>
    <axis xyz="0 0 1"/>
    <limit effort="1" velocity="20"/>
    <joint_properties friction="10000.0"/>
  </joint>
  <!-- <gazebo>
			<plugin name="gazebo_ros_joint_state_publisher"
				filename="libgazebo_ros_joint_state_publisher.so">
				<update_rate>20</update_rate>
				<joint_name>Rouleau_a_${name_roueholonome}</joint_name>
				<joint_name>Rouleau_b_${name_roueholonome}</joint_name>
				<joint_name>Rouleau_c_${name_roueholonome}</joint_name>
				<joint_name>Rouleau_d_${name_roueholonome}</joint_name>
				<joint_name>Rouleau_e_${name_roueholonome}</joint_name>
				<joint_name>Rouleau_f_${name_roueholonome}</joint_name>
				<joint_name>Rouleau_g_${name_roueholonome}</joint_name>
				<joint_name>Rouleau_h_${name_roueholonome}</joint_name>
				<joint_name>Rouleau_i_${name_roueholonome}</joint_name>
				<joint_name>Rouleau_j_${name_roueholonome}</joint_name>
				<joint_name>joint_wheel_${name_roueholonome}</joint_name>
			</plugin>
		</gazebo> -->
  <link name="roueholonome2">
    <visual>
      <origin rpy="1.570796326794896558 1.570796326794896558 0" xyz="0 0 0"/>
      <geometry>
        <mesh filename="file:///home/floris/ros2_ws/install/robot_description/share/robot_description/urdf/holonomic_wheel/roueholonome.stl"/>
      </geometry>
      <material name="roueholonome_material">
        <color rgba="0.80000000000000004441 0.80000000000000004441 0.80000000000000004441 1.0"/>
      </material>
    </visual>
    <collision>
      <origin rpy="1.570796326794896558 1.570796326794896558 0" xyz="0 0 0"/>
      <geometry>
        <mesh filename="file:///home/floris/ros2_ws/install/robot_description/share/robot_description/urdf/holonomic_wheel/roueholonome.stl"/>
      </geometry>
    </collision>
    <inertial>
      <origin rpy="0 0 0" xyz="-2.5184848675754577033e-17 4.8001766176252168599e-18 -0.0090500000000000198341"/>
      <mass value="0.073"/>
      <inertia ixx="1.923702083333333e-05" ixy="0.0" ixz="0.0" iyy="1.923702083333333e-05" iyz="0.0" izz="3.285e-05"/>
    </inertial>
  </link>
  <gazebo reference="roueholonome2">
    <material>Gazebo/Grey</material>
    <mu1>100.0</mu1>
    <mu2>100.8</mu2>
    <kp>500000.0</kp>
    <kd>10.0</kd>
    <min_depth>0.1</min_depth>
    <maxVel>0.1</maxVel>
  </gazebo>
  <link name="rouleau_1_roueholonome2">
    <visual>
      <origin rpy="-1.570796326794896558 7.4458241183643537248e-17 -2.2931001679521526839e-18" xyz="0 -6.9388939039072283776e-18 -1.3660947373317355868e-17"/>
      <geometry>
        <mesh filename="file:///home/floris/ros2_ws/install/robot_description/share/robot_description/urdf/holonomic_wheel/rouleau.stl"/>
      </geometry>
      <material name="rouleau_material">
        <color rgba="0.16078431372549020772 0.16078431372549020772 0.16078431372549020772 1.0"/>
      </material>
    </visual>
    <collision>
      <origin rpy="-1.570796326794896558 7.4458241183643537248e-17 -2.2931001679521526839e-18" xyz="0 -6.9388939039072283776e-18 -1.3660947373317355868e-17"/>
      <geometry>
        <mesh filename="file:///home/floris/ros2_ws/install/robot_description/share/robot_description/urdf/holonomic_wheel/rouleau.stl"/>
      </geometry>
    </collision>
    <inertial>
      <origin rpy="0 0 0" xyz="-1.3533020587659002873e-19 -6.9388939039072283776e-18 -7.6373245842409416038e-17"/>
      <mass value="0.01"/>
      <inertia ixx="4.4145833333333327e-07" ixy="0.0" ixz="0.0" iyy="4.4145833333333327e-07" iyz="0.0" izz="2.8125e-07"/>
    </inertial>
  </link>
  <gazebo reference="rouleau_1_roueholonome2">
    <material>Gazebo/Black</material>
    <mu1>100.0</mu1>
    <mu2>100.8</mu2>
    <kp>500000.0</kp>
    <kd>10.0</kd>
    <min_depth>0.1</min_depth>
    <maxVel>0.1</maxVel>
  </gazebo>
  <joint name="Rouleau_a_roueholonome2" type="continuous">
    <origin rpy="-0.62831853071795829013 1.570796326794896558 0" xyz="-0.013107611126122130016 0.018041078974561301773 -0.015600000000000002753"/>
    <parent link="roueholonome2"/>
    <child link="rouleau_1_roueholonome2"/>
    <axis xyz="0 0 1"/>
    <limit effort="1" velocity="20"/>
    <joint_properties friction="10000.0"/>
  </joint>
  <link name="rouleau_2_roueholonome2">
    <visual>
      <origin rpy="-1.570796326794896558 1.704115477206629922e-17 1.0069492273628905161e-16" xyz="0 3.4694469519536141888e-18 -3.4694469519536141888e-18"/>
      <geometry>
        <mesh filename="file:///home/floris/ros2_ws/install/robot_description/share/robot_description/urdf/holonomic_wheel/rouleau.stl"/>
      </geometry>
      <material name="rouleau_material">
        <color rgba="0.16078431372549020772 0.16078431372549020772 0.16078431372549020772 1.0"/>
      </material>
    </visual>
    <collision>
      <origin rpy="-1.570796326794896558 1.704115477206629922e-17 1.0069492273628905161e-16" xyz="0 3.4694469519536141888e-18 -3.4694469519536141888e-18"/>
      <geometry>
        <mesh filename="file:///home/floris/ros2_ws/install/robot_description/share/robot_description/urdf/holonomic_wheel/rouleau.stl"/>
      </geometry>
    </collision>
    <inertial>
      <origin rpy="0 0 0" xyz="-1.3533020587657876204e-19 3.4694469519536203518e-18 -6.6181745421045662032e-17"/>
      <mass value="0.01"/>
      <inertia ixx="4.4145833333333327e-07" ixy="0.0" ixz="0.0" iyy="4.4145833333333327e-07" iyz="0.0" izz="2.8125e-07"/>
    </inertial>
  </link>
  <gazebo reference="rouleau_2_roueholonome2">
    <material>Gazebo/Black</material>
    <mu1>100.0</mu1>
    <mu2>100.8</mu2>
    <kp>500000.0</kp>
    <kd>10.0</kd>
    <min_depth>0.1</min_depth>
    <maxVel>0.1</maxVel>
  </gazebo>
  <joint name="Rouleau_b_roueholonome2" type="continuous">
    <origin rpy="-1.8849555921538763137 1.570796326794896558 0" xyz="-0.02120856031338196751 -0.0068910789745613692386 -0.015599999999999974998"/>
    <parent link="roueholonome2"/>
    <child link="rouleau_2_roueholonome2"/>
    <axis xyz="0 0 1"/>
    <limit effort="1" velocity="20"/>
    <joint_properties friction="10000.0"/>
  </joint>
  <link name="rouleau_3_roueholonome2">
    <visual>
      <origin rpy="-1.57079632679489678 -3.8858620800219972321e-17 1.4515871623615415173e-17" xyz="-2.7755575615628913511e-17 -5.2041704279304212832e-18 3.4694469519536141888e-18"/>
      <geometry>
        <mesh filename="file:///home/floris/ros2_ws/install/robot_description/share/robot_description/urdf/holonomic_wheel/rouleau.stl"/>
      </geometry>
      <material name="rouleau_material">
        <color rgba="0.16078431372549020772 0.16078431372549020772 0.16078431372549020772 1.0"/>
      </material>
    </visual>
    <collision>
      <origin rpy="-1.57079632679489678 -3.8858620800219972321e-17 1.4515871623615415173e-17" xyz="-2.7755575615628913511e-17 -5.2041704279304212832e-18 3.4694469519536141888e-18"/>
      <geometry>
        <mesh filename="file:///home/floris/ros2_ws/install/robot_description/share/robot_description/urdf/holonomic_wheel/rouleau.stl"/>
      </geometry>
    </collision>
    <inertial>
      <origin rpy="0 0 0" xyz="-2.7890905821505490852e-17 -5.2041704279304320684e-18 -5.9242851517138445981e-17"/>
      <mass value="0.01"/>
      <inertia ixx="4.4145833333333327e-07" ixy="0.0" ixz="0.0" iyy="4.4145833333333327e-07" iyz="0.0" izz="2.8125e-07"/>
    </inertial>
  </link>
  <gazebo reference="rouleau_3_roueholonome2">
    <material>Gazebo/Black</material>
    <mu1>100.0</mu1>
    <mu2>100.8</mu2>
    <kp>500000.0</kp>
    <kd>10.0</kd>
    <min_depth>0.1</min_depth>
    <maxVel>0.1</maxVel>
  </gazebo>
  <joint name="Rouleau_c_roueholonome2" type="continuous">
    <origin rpy="2.2204460492503130808e-16 1.570796326794896558 0" xyz="-6.9388939039072283776e-18 -0.022300000000000003847 -0.015600000000000002753"/>
    <parent link="roueholonome2"/>
    <child link="rouleau_3_roueholonome2"/>
    <axis xyz="0 0 1"/>
    <limit effort="1" velocity="20"/>
    <joint_properties friction="10000.0"/>
  </joint>
  <link name="rouleau_4_roueholonome2">
    <visual>
      <origin rpy="-1.57079632679489678 2.2968870007964204446e-18 -1.2816475377239519703e-17" xyz="0 -5.2041704279304212832e-18 6.9388939039072283776e-18"/>
      <geometry>
        <mesh filename="file:///home/floris/ros2_ws/install/robot_description/share/robot_description/urdf/holonomic_wheel/rouleau.stl"/>
      </geometry>
      <material name="rouleau_material">
        <color rgba="0.16078431372549020772 0.16078431372549020772 0.16078431372549020772 1.0"/>
      </material>
    </visual>
    <collision>
      <origin rpy="-1.57079632679489678 2.2968870007964204446e-18 -1.2816475377239519703e-17" xyz="0 -5.2041704279304212832e-18 6.9388939039072283776e-18"/>
      <geometry>
        <mesh filename="file:///home/floris/ros2_ws/install/robot_description/share/robot_description/urdf/holonomic_wheel/rouleau.stl"/>
      </geometry>
    </collision>
    <inertial>
      <origin rpy="0 0 0" xyz="-1.3533020587658461205e-19 -5.2041704279304251351e-18 -5.5773404565184819466e-17"/>
      <mass value="0.01"/>
      <inertia ixx="4.4145833333333327e-07" ixy="0.0" ixz="0.0" iyy="4.4145833333333327e-07" iyz="0.0" izz="2.8125e-07"/>
    </inertial>
  </link>
  <gazebo reference="rouleau_4_roueholonome2">
    <material>Gazebo/Black</material>
    <mu1>100.0</mu1>
    <mu2>100.8</mu2>
    <kp>500000.0</kp>
    <kd>10.0</kd>
    <min_depth>0.1</min_depth>
    <maxVel>0.1</maxVel>
  </gazebo>
  <joint name="Rouleau_d_roueholonome2" type="continuous">
    <origin rpy="-1.2566370614359168023 1.570796326794896558 0" xyz="0.021208560313381925877 -0.006891078974561298115 -0.015600000000000002753"/>
    <parent link="roueholonome2"/>
    <child link="rouleau_4_roueholonome2"/>
    <axis xyz="0 0 1"/>
    <limit effort="1" velocity="20"/>
    <joint_properties friction="10000.0"/>
  </joint>
  <link name="rouleau_5_roueholonome2">
    <visual>
      <origin rpy="-1.570796326794896558 -3.1610276974795425021e-18 9.1157131572497391962e-18" xyz="-2.7755575615628913511e-17 3.4694469519536141888e-18 3.4694469519536141888e-18"/>
      <geometry>
        <mesh filename="file:///home/floris/ros2_ws/install/robot_description/share/robot_description/urdf/holonomic_wheel/rouleau.stl"/>
      </geometry>
      <material name="rouleau_material">
        <color rgba="0.16078431372549020772 0.16078431372549020772 0.16078431372549020772 1.0"/>
      </material>
    </visual>
    <collision>
      <origin rpy="-1.570796326794896558 -3.1610276974795425021e-18 9.1157131572497391962e-18" xyz="-2.7755575615628913511e-17 3.4694469519536141888e-18 3.4694469519536141888e-18"/>
      <geometry>
        <mesh filename="file:///home/floris/ros2_ws/install/robot_description/share/robot_description/urdf/holonomic_wheel/rouleau.stl"/>
      </geometry>
    </collision>
    <inertial>
      <origin rpy="0 0 0" xyz="-2.7890905821505497015e-17 3.4694469519536134185e-18 -5.9242851517138445981e-17"/>
      <mass value="0.01"/>
      <inertia ixx="4.4145833333333327e-07" ixy="0.0" ixz="0.0" iyy="4.4145833333333327e-07" iyz="0.0" izz="2.8125e-07"/>
    </inertial>
  </link>
  <gazebo reference="rouleau_5_roueholonome2">
    <material>Gazebo/Black</material>
    <mu1>100.0</mu1>
    <mu2>100.8</mu2>
    <kp>500000.0</kp>
    <kd>10.0</kd>
    <min_depth>0.1</min_depth>
    <maxVel>0.1</maxVel>
  </gazebo>
  <joint name="Rouleau_e_roueholonome2" type="continuous">
    <origin rpy="0.62831853071795817911 1.570796326794896558 0" xyz="0.013107611126122100526 0.018041078974561364223 -0.015600000000000002753"/>
    <parent link="roueholonome2"/>
    <child link="rouleau_5_roueholonome2"/>
    <axis xyz="0 0 1"/>
    <limit effort="1" velocity="20"/>
    <joint_properties friction="10000.0"/>
  </joint>
  <link name="rouleau_6_roueholonome2">
    <visual>
      <origin rpy="-1.57079632679489678 -3.8858615837136297003e-17 1.4515871623615415173e-17" xyz="0 0 5.2041704279304212832e-18"/>
      <geometry>
        <mesh filename="file:///home/floris/ros2_ws/install/robot_description/share/robot_description/urdf/holonomic_wheel/rouleau.stl"/>
      </geometry>
      <material name="rouleau_material">
        <color rgba="0.16078431372549020772 0.16078431372549020772 0.16078431372549020772 1.0"/>
      </material>
    </visual>
    <collision>
      <origin rpy="-1.57079632679489678 -3.8858615837136297003e-17 1.4515871623615415173e-17" xyz="0 0 5.2041704279304212832e-18"/>
      <geometry>
        <mesh filename="file:///home/floris/ros2_ws/install/robot_description/share/robot_description/urdf/holonomic_wheel/rouleau.stl"/>
      </geometry>
    </collision>
    <inertial>
      <origin rpy="0 0 0" xyz="-1.3533020587657560833e-19 -4.0005310894682744636e-33 -5.7508128041161638886e-17"/>
      <mass value="0.01"/>
      <inertia ixx="4.4145833333333327e-07" ixy="0.0" ixz="0.0" iyy="4.4145833333333327e-07" iyz="0.0" izz="2.8125e-07"/>
    </inertial>
  </link>
  <gazebo reference="rouleau_6_roueholonome2">
    <material>Gazebo/Black</material>
    <mu1>100.0</mu1>
    <mu2>100.8</mu2>
    <kp>500000.0</kp>
    <kd>10.0</kd>
    <min_depth>0.1</min_depth>
    <maxVel>0.1</maxVel>
  </gazebo>
  <joint name="Rouleau_f_roueholonome2" type="continuous">
    <origin rpy="-0 1.570796326794896558 0" xyz="-8.6736173798840354721e-18 0.022299999999999993439 -0.0025000000000000022204"/>
    <parent link="roueholonome2"/>
    <child link="rouleau_6_roueholonome2"/>
    <axis xyz="0 0 1"/>
    <limit effort="1" velocity="20"/>
    <joint_properties friction="10000.0"/>
  </joint>
  <link name="rouleau_7_roueholonome2">
    <visual>
      <origin rpy="-1.57079632679489678 2.2968870007964204446e-18 -1.2816475377239519703e-17" xyz="0 -6.9388939039072283776e-18 5.2041704279304212832e-18"/>
      <geometry>
        <mesh filename="file:///home/floris/ros2_ws/install/robot_description/share/robot_description/urdf/holonomic_wheel/rouleau.stl"/>
      </geometry>
      <material name="rouleau_material">
        <color rgba="0.16078431372549020772 0.16078431372549020772 0.16078431372549020772 1.0"/>
      </material>
    </visual>
    <collision>
      <origin rpy="-1.57079632679489678 2.2968870007964204446e-18 -1.2816475377239519703e-17" xyz="0 -6.9388939039072283776e-18 5.2041704279304212832e-18"/>
      <geometry>
        <mesh filename="file:///home/floris/ros2_ws/install/robot_description/share/robot_description/urdf/holonomic_wheel/rouleau.stl"/>
      </geometry>
    </collision>
    <inertial>
      <origin rpy="0 0 0" xyz="-1.3533020587658461205e-19 -6.9388939039072329999e-18 -5.750812804116162656e-17"/>
      <mass value="0.01"/>
      <inertia ixx="4.4145833333333327e-07" ixy="0.0" ixz="0.0" iyy="4.4145833333333327e-07" iyz="0.0" izz="2.8125e-07"/>
    </inertial>
  </link>
  <gazebo reference="rouleau_7_roueholonome2">
    <material>Gazebo/Black</material>
    <mu1>100.0</mu1>
    <mu2>100.8</mu2>
    <kp>500000.0</kp>
    <kd>10.0</kd>
    <min_depth>0.1</min_depth>
    <maxVel>0.1</maxVel>
  </gazebo>
  <joint name="Rouleau_g_roueholonome2" type="continuous">
    <origin rpy="-1.2566370614359168023 1.570796326794896558 0" xyz="-0.021208560313381932816 0.0068910789745613033191 -0.0025000000000000022204"/>
    <parent link="roueholonome2"/>
    <child link="rouleau_7_roueholonome2"/>
    <axis xyz="0 0 1"/>
    <limit effort="1" velocity="20"/>
    <joint_properties friction="10000.0"/>
  </joint>
  <link name="rouleau_8_roueholonome2">
    <visual>
      <origin rpy="-1.570796326794896558 -3.1610276974795425021e-18 9.1157131572497391962e-18" xyz="0 -1.0408340855860842566e-17 -3.4694469519536141888e-18"/>
      <geometry>
        <mesh filename="file:///home/floris/ros2_ws/install/robot_description/share/robot_description/urdf/holonomic_wheel/rouleau.stl"/>
      </geometry>
      <material name="rouleau_material">
        <color rgba="0.16078431372549020772 0.16078431372549020772 0.16078431372549020772 1.0"/>
      </material>
    </visual>
    <collision>
      <origin rpy="-1.570796326794896558 -3.1610276974795425021e-18 9.1157131572497391962e-18" xyz="0 -1.0408340855860842566e-17 -3.4694469519536141888e-18"/>
      <geometry>
        <mesh filename="file:///home/floris/ros2_ws/install/robot_description/share/robot_description/urdf/holonomic_wheel/rouleau.stl"/>
      </geometry>
    </collision>
    <inertial>
      <origin rpy="0 0 0" xyz="-1.3533020587658068797e-19 -1.0408340855860842566e-17 -6.6181745421045674358e-17"/>
      <mass value="0.01"/>
      <inertia ixx="4.4145833333333327e-07" ixy="0.0" ixz="0.0" iyy="4.4145833333333327e-07" iyz="0.0" izz="2.8125e-07"/>
    </inertial>
  </link>
  <gazebo reference="rouleau_8_roueholonome2">
    <material>Gazebo/Black</material>
    <mu1>100.0</mu1>
    <mu2>100.8</mu2>
    <kp>500000.0</kp>
    <kd>10.0</kd>
    <min_depth>0.1</min_depth>
    <maxVel>0.1</maxVel>
  </gazebo>
  <joint name="Rouleau_h_roueholonome2" type="continuous">
    <origin rpy="0.62831853071795817911 1.570796326794896558 0" xyz="-0.013107611126122147363 -0.018041078974561343407 -0.0024999999999999744649"/>
    <parent link="roueholonome2"/>
    <child link="rouleau_8_roueholonome2"/>
    <axis xyz="0 0 1"/>
    <limit effort="1" velocity="20"/>
    <joint_properties friction="10000.0"/>
  </joint>
  <link name="rouleau_9_roueholonome2">
    <visual>
      <origin rpy="-1.570796326794896558 7.4458252970967266128e-17 -2.2931034766746028961e-18" xyz="0 0 -2.4936649967166601982e-18"/>
      <geometry>
        <mesh filename="file:///home/floris/ros2_ws/install/robot_description/share/robot_description/urdf/holonomic_wheel/rouleau.stl"/>
      </geometry>
      <material name="rouleau_material">
        <color rgba="0.16078431372549020772 0.16078431372549020772 0.16078431372549020772 1.0"/>
      </material>
    </visual>
    <collision>
      <origin rpy="-1.570796326794896558 7.4458252970967266128e-17 -2.2931034766746028961e-18" xyz="0 0 -2.4936649967166601982e-18"/>
      <geometry>
        <mesh filename="file:///home/floris/ros2_ws/install/robot_description/share/robot_description/urdf/holonomic_wheel/rouleau.stl"/>
      </geometry>
    </collision>
    <inertial>
      <origin rpy="0 0 0" xyz="-1.353302058765900528e-19 -8.1870457482636967244e-35 -6.5205963465808720368e-17"/>
      <mass value="0.01"/>
      <inertia ixx="4.4145833333333327e-07" ixy="0.0" ixz="0.0" iyy="4.4145833333333327e-07" iyz="0.0" izz="2.8125e-07"/>
    </inertial>
  </link>
  <gazebo reference="rouleau_9_roueholonome2">
    <material>Gazebo/Black</material>
    <mu1>100.0</mu1>
    <mu2>100.8</mu2>
    <kp>500000.0</kp>
    <kd>10.0</kd>
    <min_depth>0.1</min_depth>
    <maxVel>0.1</maxVel>
  </gazebo>
  <joint name="Rouleau_i_roueholonome2" type="continuous">
    <origin rpy="-0.62831853071795884524 1.570796326794896558 0" xyz="0.013107611126122112669 -0.018041078974561298304 -0.0025000000000000022204"/>
    <parent link="roueholonome2"/>
    <child link="rouleau_9_roueholonome2"/>
    <axis xyz="0 0 1"/>
    <limit effort="1" velocity="20"/>
    <joint_properties friction="10000.0"/>
  </joint>
  <link name="rouleau_10_roueholonome2">
    <visual>
      <origin rpy="-1.570796326794896558 1.704115477206629922e-17 1.0069492273628905161e-16" xyz="0 0 3.4694469519536141888e-18"/>
      <geometry>
        <mesh filename="file:///home/floris/ros2_ws/install/robot_description/share/robot_description/urdf/holonomic_wheel/rouleau.stl"/>
      </geometry>
      <material name="rouleau_material">
        <color rgba="0.16078431372549020772 0.16078431372549020772 0.16078431372549020772 1.0"/>
      </material>
    </visual>
    <collision>
      <origin rpy="-1.570796326794896558 1.704115477206629922e-17 1.0069492273628905161e-16" xyz="0 0 3.4694469519536141888e-18"/>
      <geometry>
        <mesh filename="file:///home/floris/ros2_ws/install/robot_description/share/robot_description/urdf/holonomic_wheel/rouleau.stl"/>
      </geometry>
    </collision>
    <inertial>
      <origin rpy="0 0 0" xyz="-1.3533020587657876204e-19 6.4315019349350432793e-33 -5.9242851517138433655e-17"/>
      <mass value="0.01"/>
      <inertia ixx="4.4145833333333327e-07" ixy="0.0" ixz="0.0" iyy="4.4145833333333327e-07" iyz="0.0" izz="2.8125e-07"/>
    </inertial>
  </link>
  <gazebo reference="rouleau_10_roueholonome2">
    <material>Gazebo/Black</material>
    <mu1>100.0</mu1>
    <mu2>100.8</mu2>
    <kp>500000.0</kp>
    <kd>10.0</kd>
    <min_depth>0.1</min_depth>
    <maxVel>0.1</maxVel>
  </gazebo>
  <joint name="Rouleau_j_roueholonome2" type="continuous">
    <origin rpy="-1.8849555921538763137 1.570796326794896558 0" xyz="0.021208560313381953633 0.0068910789745613831164 -0.0025000000000000022204"/>
    <parent link="roueholonome2"/>
    <child link="rouleau_10_roueholonome2"/>
    <axis xyz="0 0 1"/>
    <limit effort="1" velocity="20"/>
    <joint_properties friction="10000.0"/>
  </joint>
  <joint name="joint_wheel_roueholonome2" type="continuous">
    <origin rpy="-1.5707963372259698964 -1.578796498993817555e-16 -1.5135513408355580736e-08" xyz="-9.4218689434714475786e-10 -0.13324999991488650775 0.018160000618041127751"/>
    <parent link="base_link"/>
    <child link="roueholonome2"/>
    <axis xyz="0 0 1"/>
    <limit effort="1" velocity="20"/>
    <joint_properties friction="10000.0"/>
  </joint>
  <!-- <gazebo>
			<plugin name="gazebo_ros_joint_state_publisher"
				filename="libgazebo_ros_joint_state_publisher.so">
				<update_rate>20</update_rate>
				<joint_name>Rouleau_a_${name_roueholonome}</joint_name>
				<joint_name>Rouleau_b_${name_roueholonome}</joint_name>
				<joint_name>Rouleau_c_${name_roueholonome}</joint_name>
				<joint_name>Rouleau_d_${name_roueholonome}</joint_name>
				<joint_name>Rouleau_e_${name_roueholonome}</joint_name>
				<joint_name>Rouleau_f_${name_roueholonome}</joint_name>
				<joint_name>Rouleau_g_${name_roueholonome}</joint_name>
				<joint_name>Rouleau_h_${name_roueholonome}</joint_name>
				<joint_name>Rouleau_i_${name_roueholonome}</joint_name>
				<joint_name>Rouleau_j_${name_roueholonome}</joint_name>
				<joint_name>joint_wheel_${name_roueholonome}</joint_name>
			</plugin>
		</gazebo> -->
  <link name="roueholonome3">
    <visual>
      <origin rpy="1.570796326794896558 1.570796326794896558 0" xyz="0 0 0"/>
      <geometry>
        <mesh filename="file:///home/floris/ros2_ws/install/robot_description/share/robot_description/urdf/holonomic_wheel/roueholonome.stl"/>
      </geometry>
      <material name="roueholonome_material">
        <color rgba="0.80000000000000004441 0.80000000000000004441 0.80000000000000004441 1.0"/>
      </material>
    </visual>
    <collision>
      <origin rpy="1.570796326794896558 1.570796326794896558 0" xyz="0 0 0"/>
      <geometry>
        <mesh filename="file:///home/floris/ros2_ws/install/robot_description/share/robot_description/urdf/holonomic_wheel/roueholonome.stl"/>
      </geometry>
    </collision>
    <inertial>
      <origin rpy="0 0 0" xyz="-2.5184848675754577033e-17 4.8001766176252168599e-18 -0.0090500000000000198341"/>
      <mass value="0.073"/>
      <inertia ixx="1.923702083333333e-05" ixy="0.0" ixz="0.0" iyy="1.923702083333333e-05" iyz="0.0" izz="3.285e-05"/>
    </inertial>
  </link>
  <gazebo reference="roueholonome3">
    <material>Gazebo/Grey</material>
    <mu1>100.0</mu1>
    <mu2>100.8</mu2>
    <kp>500000.0</kp>
    <kd>10.0</kd>
    <min_depth>0.1</min_depth>
    <maxVel>0.1</maxVel>
  </gazebo>
  <link name="rouleau_1_roueholonome3">
    <visual>
      <origin rpy="-1.570796326794896558 7.4458241183643537248e-17 -2.2931001679521526839e-18" xyz="0 -6.9388939039072283776e-18 -1.3660947373317355868e-17"/>
      <geometry>
        <mesh filename="file:///home/floris/ros2_ws/install/robot_description/share/robot_description/urdf/holonomic_wheel/rouleau.stl"/>
      </geometry>
      <material name="rouleau_material">
        <color rgba="0.16078431372549020772 0.16078431372549020772 0.16078431372549020772 1.0"/>
      </material>
    </visual>
    <collision>
      <origin rpy="-1.570796326794896558 7.4458241183643537248e-17 -2.2931001679521526839e-18" xyz="0 -6.9388939039072283776e-18 -1.3660947373317355868e-17"/>
      <geometry>
        <mesh filename="file:///home/floris/ros2_ws/install/robot_description/share/robot_description/urdf/holonomic_wheel/rouleau.stl"/>
      </geometry>
    </collision>
    <inertial>
      <origin rpy="0 0 0" xyz="-1.3533020587659002873e-19 -6.9388939039072283776e-18 -7.6373245842409416038e-17"/>
      <mass value="0.01"/>
      <inertia ixx="4.4145833333333327e-07" ixy="0.0" ixz="0.0" iyy="4.4145833333333327e-07" iyz="0.0" izz="2.8125e-07"/>
    </inertial>
  </link>
  <gazebo reference="rouleau_1_roueholonome3">
    <material>Gazebo/Black</material>
    <mu1>100.0</mu1>
    <mu2>100.8</mu2>
    <kp>500000.0</kp>
    <kd>10.0</kd>
    <min_depth>0.1</min_depth>
    <maxVel>0.1</maxVel>
  </gazebo>
  <joint name="Rouleau_a_roueholonome3" type="continuous">
    <origin rpy="-0.62831853071795829013 1.570796326794896558 0" xyz="-0.013107611126122130016 0.018041078974561301773 -0.015600000000000002753"/>
    <parent link="roueholonome3"/>
    <child link="rouleau_1_roueholonome3"/>
    <axis xyz="0 0 1"/>
    <limit effort="1" velocity="20"/>
    <joint_properties friction="10000.0"/>
  </joint>
  <link name="rouleau_2_roueholonome3">
    <visual>
      <origin rpy="-1.570796326794896558 1.704115477206629922e-17 1.0069492273628905161e-16" xyz="0 3.4694469519536141888e-18 -3.4694469519536141888e-18"/>
      <geometry>
        <mesh filename="file:///home/floris/ros2_ws/install/robot_description/share/robot_description/urdf/holonomic_wheel/rouleau.stl"/>
      </geometry>
      <material name="rouleau_material">
        <color rgba="0.16078431372549020772 0.16078431372549020772 0.16078431372549020772 1.0"/>
      </material>
    </visual>
    <collision>
      <origin rpy="-1.570796326794896558 1.704115477206629922e-17 1.0069492273628905161e-16" xyz="0 3.4694469519536141888e-18 -3.4694469519536141888e-18"/>
      <geometry>
        <mesh filename="file:///home/floris/ros2_ws/install/robot_description/share/robot_description/urdf/holonomic_wheel/rouleau.stl"/>
      </geometry>
    </collision>
    <inertial>
      <origin rpy="0 0 0" xyz="-1.3533020587657876204e-19 3.4694469519536203518e-18 -6.6181745421045662032e-17"/>
      <mass value="0.01"/>
      <inertia ixx="4.4145833333333327e-07" ixy="0.0" ixz="0.0" iyy="4.4145833333333327e-07" iyz="0.0" izz="2.8125e-07"/>
    </inertial>
  </link>
  <gazebo reference="rouleau_2_roueholonome3">
    <material>Gazebo/Black</material>
    <mu1>100.0</mu1>
    <mu2>100.8</mu2>
    <kp>500000.0</kp>
    <kd>10.0</kd>
    <min_depth>0.1</min_depth>
    <maxVel>0.1</maxVel>
  </gazebo>
  <joint name="Rouleau_b_roueholonome3" type="continuous">
    <origin rpy="-1.8849555921538763137 1.570796326794896558 0" xyz="-0.02120856031338196751 -0.0068910789745613692386 -0.015599999999999974998"/>
    <parent link="roueholonome3"/>
    <child link="rouleau_2_roueholonome3"/>
    <axis xyz="0 0 1"/>
    <limit effort="1" velocity="20"/>
    <joint_properties friction="10000.0"/>
  </joint>
  <link name="rouleau_3_roueholonome3">
    <visual>
      <origin rpy="-1.57079632679489678 -3.8858620800219972321e-17 1.4515871623615415173e-17" xyz="-2.7755575615628913511e-17 -5.2041704279304212832e-18 3.4694469519536141888e-18"/>
      <geometry>
        <mesh filename="file:///home/floris/ros2_ws/install/robot_description/share/robot_description/urdf/holonomic_wheel/rouleau.stl"/>
      </geometry>
      <material name="rouleau_material">
        <color rgba="0.16078431372549020772 0.16078431372549020772 0.16078431372549020772 1.0"/>
      </material>
    </visual>
    <collision>
      <origin rpy="-1.57079632679489678 -3.8858620800219972321e-17 1.4515871623615415173e-17" xyz="-2.7755575615628913511e-17 -5.2041704279304212832e-18 3.4694469519536141888e-18"/>
      <geometry>
        <mesh filename="file:///home/floris/ros2_ws/install/robot_description/share/robot_description/urdf/holonomic_wheel/rouleau.stl"/>
      </geometry>
    </collision>
    <inertial>
      <origin rpy="0 0 0" xyz="-2.7890905821505490852e-17 -5.2041704279304320684e-18 -5.9242851517138445981e-17"/>
      <mass value="0.01"/>
      <inertia ixx="4.4145833333333327e-07" ixy="0.0" ixz="0.0" iyy="4.4145833333333327e-07" iyz="0.0" izz="2.8125e-07"/>
    </inertial>
  </link>
  <gazebo reference="rouleau_3_roueholonome3">
    <material>Gazebo/Black</material>
    <mu1>100.0</mu1>
    <mu2>100.8</mu2>
    <kp>500000.0</kp>
    <kd>10.0</kd>
    <min_depth>0.1</min_depth>
    <maxVel>0.1</maxVel>
  </gazebo>
  <joint name="Rouleau_c_roueholonome3" type="continuous">
    <origin rpy="2.2204460492503130808e-16 1.570796326794896558 0" xyz="-6.9388939039072283776e-18 -0.022300000000000003847 -0.015600000000000002753"/>
    <parent link="roueholonome3"/>
    <child link="rouleau_3_roueholonome3"/>
    <axis xyz="0 0 1"/>
    <limit effort="1" velocity="20"/>
    <joint_properties friction="10000.0"/>
  </joint>
  <link name="rouleau_4_roueholonome3">
    <visual>
      <origin rpy="-1.57079632679489678 2.2968870007964204446e-18 -1.2816475377239519703e-17" xyz="0 -5.2041704279304212832e-18 6.9388939039072283776e-18"/>
      <geometry>
        <mesh filename="file:///home/floris/ros2_ws/install/robot_description/share/robot_description/urdf/holonomic_wheel/rouleau.stl"/>
      </geometry>
      <material name="rouleau_material">
        <color rgba="0.16078431372549020772 0.16078431372549020772 0.16078431372549020772 1.0"/>
      </material>
    </visual>
    <collision>
      <origin rpy="-1.57079632679489678 2.2968870007964204446e-18 -1.2816475377239519703e-17" xyz="0 -5.2041704279304212832e-18 6.9388939039072283776e-18"/>
      <geometry>
        <mesh filename="file:///home/floris/ros2_ws/install/robot_description/share/robot_description/urdf/holonomic_wheel/rouleau.stl"/>
      </geometry>
    </collision>
    <inertial>
      <origin rpy="0 0 0" xyz="-1.3533020587658461205e-19 -5.2041704279304251351e-18 -5.5773404565184819466e-17"/>
      <mass value="0.01"/>
      <inertia ixx="4.4145833333333327e-07" ixy="0.0" ixz="0.0" iyy="4.4145833333333327e-07" iyz="0.0" izz="2.8125e-07"/>
    </inertial>
  </link>
  <gazebo reference="rouleau_4_roueholonome3">
    <material>Gazebo/Black</material>
    <mu1>100.0</mu1>
    <mu2>100.8</mu2>
    <kp>500000.0</kp>
    <kd>10.0</kd>
    <min_depth>0.1</min_depth>
    <maxVel>0.1</maxVel>
  </gazebo>
  <joint name="Rouleau_d_roueholonome3" type="continuous">
    <origin rpy="-1.2566370614359168023 1.570796326794896558 0" xyz="0.021208560313381925877 -0.006891078974561298115 -0.015600000000000002753"/>
    <parent link="roueholonome3"/>
    <child link="rouleau_4_roueholonome3"/>
    <axis xyz="0 0 1"/>
    <limit effort="1" velocity="20"/>
    <joint_properties friction="10000.0"/>
  </joint>
  <link name="rouleau_5_roueholonome3">
    <visual>
      <origin rpy="-1.570796326794896558 -3.1610276974795425021e-18 9.1157131572497391962e-18" xyz="-2.7755575615628913511e-17 3.4694469519536141888e-18 3.4694469519536141888e-18"/>
      <geometry>
        <mesh filename="file:///home/floris/ros2_ws/install/robot_description/share/robot_description/urdf/holonomic_wheel/rouleau.stl"/>
      </geometry>
      <material name="rouleau_material">
        <color rgba="0.16078431372549020772 0.16078431372549020772 0.16078431372549020772 1.0"/>
      </material>
    </visual>
    <collision>
      <origin rpy="-1.570796326794896558 -3.1610276974795425021e-18 9.1157131572497391962e-18" xyz="-2.7755575615628913511e-17 3.4694469519536141888e-18 3.4694469519536141888e-18"/>
      <geometry>
        <mesh filename="file:///home/floris/ros2_ws/install/robot_description/share/robot_description/urdf/holonomic_wheel/rouleau.stl"/>
      </geometry>
    </collision>
    <inertial>
      <origin rpy="0 0 0" xyz="-2.7890905821505497015e-17 3.4694469519536134185e-18 -5.9242851517138445981e-17"/>
      <mass value="0.01"/>
      <inertia ixx="4.4145833333333327e-07" ixy="0.0" ixz="0.0" iyy="4.4145833333333327e-07" iyz="0.0" izz="2.8125e-07"/>
    </inertial>
  </link>
  <gazebo reference="rouleau_5_roueholonome3">
    <material>Gazebo/Black</material>
    <mu1>100.0</mu1>
    <mu2>100.8</mu2>
    <kp>500000.0</kp>
    <kd>10.0</kd>
    <min_depth>0.1</min_depth>
    <maxVel>0.1</maxVel>
  </gazebo>
  <joint name="Rouleau_e_roueholonome3" type="continuous">
    <origin rpy="0.62831853071795817911 1.570796326794896558 0" xyz="0.013107611126122100526 0.018041078974561364223 -0.015600000000000002753"/>
    <parent link="roueholonome3"/>
    <child link="rouleau_5_roueholonome3"/>
    <axis xyz="0 0 1"/>
    <limit effort="1" velocity="20"/>
    <joint_properties friction="10000.0"/>
  </joint>
  <link name="rouleau_6_roueholonome3">
    <visual>
      <origin rpy="-1.57079632679489678 -3.8858615837136297003e-17 1.4515871623615415173e-17" xyz="0 0 5.2041704279304212832e-18"/>
      <geometry>
        <mesh filename="file:///home/floris/ros2_ws/install/robot_description/share/robot_description/urdf/holonomic_wheel/rouleau.stl"/>
      </geometry>
      <material name="rouleau_material">
        <color rgba="0.16078431372549020772 0.16078431372549020772 0.16078431372549020772 1.0"/>
      </material>
    </visual>
    <collision>
      <origin rpy="-1.57079632679489678 -3.8858615837136297003e-17 1.4515871623615415173e-17" xyz="0 0 5.2041704279304212832e-18"/>
      <geometry>
        <mesh filename="file:///home/floris/ros2_ws/install/robot_description/share/robot_description/urdf/holonomic_wheel/rouleau.stl"/>
      </geometry>
    </collision>
    <inertial>
      <origin rpy="0 0 0" xyz="-1.3533020587657560833e-19 -4.0005310894682744636e-33 -5.7508128041161638886e-17"/>
      <mass value="0.01"/>
      <inertia ixx="4.4145833333333327e-07" ixy="0.0" ixz="0.0" iyy="4.4145833333333327e-07" iyz="0.0" izz="2.8125e-07"/>
    </inertial>
  </link>
  <gazebo reference="rouleau_6_roueholonome3">
    <material>Gazebo/Black</material>
    <mu1>100.0</mu1>
    <mu2>100.8</mu2>
    <kp>500000.0</kp>
    <kd>10.0</kd>
    <min_depth>0.1</min_depth>
    <maxVel>0.1</maxVel>
  </gazebo>
  <joint name="Rouleau_f_roueholonome3" type="continuous">
    <origin rpy="-0 1.570796326794896558 0" xyz="-8.6736173798840354721e-18 0.022299999999999993439 -0.0025000000000000022204"/>
    <parent link="roueholonome3"/>
    <child link="rouleau_6_roueholonome3"/>
    <axis xyz="0 0 1"/>
    <limit effort="1" velocity="20"/>
    <joint_properties friction="10000.0"/>
  </joint>
  <link name="rouleau_7_roueholonome3">
    <visual>
      <origin rpy="-1.57079632679489678 2.2968870007964204446e-18 -1.2816475377239519703e-17" xyz="0 -6.9388939039072283776e-18 5.2041704279304212832e-18"/>
      <geometry>
        <mesh filename="file:///home/floris/ros2_ws/install/robot_description/share/robot_description/urdf/holonomic_wheel/rouleau.stl"/>
      </geometry>
      <material name="rouleau_material">
        <color rgba="0.16078431372549020772 0.16078431372549020772 0.16078431372549020772 1.0"/>
      </material>
    </visual>
    <collision>
      <origin rpy="-1.57079632679489678 2.2968870007964204446e-18 -1.2816475377239519703e-17" xyz="0 -6.9388939039072283776e-18 5.2041704279304212832e-18"/>
      <geometry>
        <mesh filename="file:///home/floris/ros2_ws/install/robot_description/share/robot_description/urdf/holonomic_wheel/rouleau.stl"/>
      </geometry>
    </collision>
    <inertial>
      <origin rpy="0 0 0" xyz="-1.3533020587658461205e-19 -6.9388939039072329999e-18 -5.750812804116162656e-17"/>
      <mass value="0.01"/>
      <inertia ixx="4.4145833333333327e-07" ixy="0.0" ixz="0.0" iyy="4.4145833333333327e-07" iyz="0.0" izz="2.8125e-07"/>
    </inertial>
  </link>
  <gazebo reference="rouleau_7_roueholonome3">
    <material>Gazebo/Black</material>
    <mu1>100.0</mu1>
    <mu2>100.8</mu2>
    <kp>500000.0</kp>
    <kd>10.0</kd>
    <min_depth>0.1</min_depth>
    <maxVel>0.1</maxVel>
  </gazebo>
  <joint name="Rouleau_g_roueholonome3" type="continuous">
    <origin rpy="-1.2566370614359168023 1.570796326794896558 0" xyz="-0.021208560313381932816 0.0068910789745613033191 -0.0025000000000000022204"/>
    <parent link="roueholonome3"/>
    <child link="rouleau_7_roueholonome3"/>
    <axis xyz="0 0 1"/>
    <limit effort="1" velocity="20"/>
    <joint_properties friction="10000.0"/>
  </joint>
  <link name="rouleau_8_roueholonome3">
    <visual>
      <origin rpy="-1.570796326794896558 -3.1610276974795425021e-18 9.1157131572497391962e-18" xyz="0 -1.0408340855860842566e-17 -3.4694469519536141888e-18"/>
      <geometry>
        <mesh filename="file:///home/floris/ros2_ws/install/robot_description/share/robot_description/urdf/holonomic_wheel/rouleau.stl"/>
      </geometry>
      <material name="rouleau_material">
        <color rgba="0.16078431372549020772 0.16078431372549020772 0.16078431372549020772 1.0"/>
      </material>
    </visual>
    <collision>
      <origin rpy="-1.570796326794896558 -3.1610276974795425021e-18 9.1157131572497391962e-18" xyz="0 -1.0408340855860842566e-17 -3.4694469519536141888e-18"/>
      <geometry>
        <mesh filename="file:///home/floris/ros2_ws/install/robot_description/share/robot_description/urdf/holonomic_wheel/rouleau.stl"/>
      </geometry>
    </collision>
    <inertial>
      <origin rpy="0 0 0" xyz="-1.3533020587658068797e-19 -1.0408340855860842566e-17 -6.6181745421045674358e-17"/>
      <mass value="0.01"/>
      <inertia ixx="4.4145833333333327e-07" ixy="0.0" ixz="0.0" iyy="4.4145833333333327e-07" iyz="0.0" izz="2.8125e-07"/>
    </inertial>
  </link>
  <gazebo reference="rouleau_8_roueholonome3">
    <material>Gazebo/Black</material>
    <mu1>100.0</mu1>
    <mu2>100.8</mu2>
    <kp>500000.0</kp>
    <kd>10.0</kd>
    <min_depth>0.1</min_depth>
    <maxVel>0.1</maxVel>
  </gazebo>
  <joint name="Rouleau_h_roueholonome3" type="continuous">
    <origin rpy="0.62831853071795817911 1.570796326794896558 0" xyz="-0.013107611126122147363 -0.018041078974561343407 -0.0024999999999999744649"/>
    <parent link="roueholonome3"/>
    <child link="rouleau_8_roueholonome3"/>
    <axis xyz="0 0 1"/>
    <limit effort="1" velocity="20"/>
    <joint_properties friction="10000.0"/>
  </joint>
  <link name="rouleau_9_roueholonome3">
    <visual>
      <origin rpy="-1.570796326794896558 7.4458252970967266128e-17 -2.2931034766746028961e-18" xyz="0 0 -2.4936649967166601982e-18"/>
      <geometry>
        <mesh filename="file:///home/floris/ros2_ws/install/robot_description/share/robot_description/urdf/holonomic_wheel/rouleau.stl"/>
      </geometry>
      <material name="rouleau_material">
        <color rgba="0.16078431372549020772 0.16078431372549020772 0.16078431372549020772 1.0"/>
      </material>
    </visual>
    <collision>
      <origin rpy="-1.570796326794896558 7.4458252970967266128e-17 -2.2931034766746028961e-18" xyz="0 0 -2.4936649967166601982e-18"/>
      <geometry>
        <mesh filename="file:///home/floris/ros2_ws/install/robot_description/share/robot_description/urdf/holonomic_wheel/rouleau.stl"/>
      </geometry>
    </collision>
    <inertial>
      <origin rpy="0 0 0" xyz="-1.353302058765900528e-19 -8.1870457482636967244e-35 -6.5205963465808720368e-17"/>
      <mass value="0.01"/>
      <inertia ixx="4.4145833333333327e-07" ixy="0.0" ixz="0.0" iyy="4.4145833333333327e-07" iyz="0.0" izz="2.8125e-07"/>
    </inertial>
  </link>
  <gazebo reference="rouleau_9_roueholonome3">
    <material>Gazebo/Black</material>
    <mu1>100.0</mu1>
    <mu2>100.8</mu2>
    <kp>500000.0</kp>
    <kd>10.0</kd>
    <min_depth>0.1</min_depth>
    <maxVel>0.1</maxVel>
  </gazebo>
  <joint name="Rouleau_i_roueholonome3" type="continuous">
    <origin rpy="-0.62831853071795884524 1.570796326794896558 0" xyz="0.013107611126122112669 -0.018041078974561298304 -0.0025000000000000022204"/>
    <parent link="roueholonome3"/>
    <child link="rouleau_9_roueholonome3"/>
    <axis xyz="0 0 1"/>
    <limit effort="1" velocity="20"/>
    <joint_properties friction="10000.0"/>
  </joint>
  <link name="rouleau_10_roueholonome3">
    <visual>
      <origin rpy="-1.570796326794896558 1.704115477206629922e-17 1.0069492273628905161e-16" xyz="0 0 3.4694469519536141888e-18"/>
      <geometry>
        <mesh filename="file:///home/floris/ros2_ws/install/robot_description/share/robot_description/urdf/holonomic_wheel/rouleau.stl"/>
      </geometry>
      <material name="rouleau_material">
        <color rgba="0.16078431372549020772 0.16078431372549020772 0.16078431372549020772 1.0"/>
      </material>
    </visual>
    <collision>
      <origin rpy="-1.570796326794896558 1.704115477206629922e-17 1.0069492273628905161e-16" xyz="0 0 3.4694469519536141888e-18"/>
      <geometry>
        <mesh filename="file:///home/floris/ros2_ws/install/robot_description/share/robot_description/urdf/holonomic_wheel/rouleau.stl"/>
      </geometry>
    </collision>
    <inertial>
      <origin rpy="0 0 0" xyz="-1.3533020587657876204e-19 6.4315019349350432793e-33 -5.9242851517138433655e-17"/>
      <mass value="0.01"/>
      <inertia ixx="4.4145833333333327e-07" ixy="0.0" ixz="0.0" iyy="4.4145833333333327e-07" iyz="0.0" izz="2.8125e-07"/>
    </inertial>
  </link>
  <gazebo reference="rouleau_10_roueholonome3">
    <material>Gazebo/Black</material>
    <mu1>100.0</mu1>
    <mu2>100.8</mu2>
    <kp>500000.0</kp>
    <kd>10.0</kd>
    <min_depth>0.1</min_depth>
    <maxVel>0.1</maxVel>
  </gazebo>
  <joint name="Rouleau_j_roueholonome3" type="continuous">
    <origin rpy="-1.8849555921538763137 1.570796326794896558 0" xyz="0.021208560313381953633 0.0068910789745613831164 -0.0025000000000000022204"/>
    <parent link="roueholonome3"/>
    <child link="rouleau_10_roueholonome3"/>
    <axis xyz="0 0 1"/>
    <limit effort="1" velocity="20"/>
    <joint_properties friction="10000.0"/>
  </joint>
  <joint name="joint_wheel_roueholonome3" type="continuous">
    <origin rpy="1.570796305932749215 3.6134297384305885703e-08 1.0471975360610779049" xyz="-0.11539788473061769747 0.06662500090107909001 0.018159998763917353098"/>
    <parent link="base_link"/>
    <child link="roueholonome3"/>
    <axis xyz="0 0 1"/>
    <limit effort="1" velocity="20"/>
    <joint_properties friction="10000.0"/>
  </joint>
  <!-- <gazebo>
			<plugin name="gazebo_ros_joint_state_publisher"
				filename="libgazebo_ros_joint_state_publisher.so">
				<update_rate>20</update_rate>
				<joint_name>Rouleau_a_${name_roueholonome}</joint_name>
				<joint_name>Rouleau_b_${name_roueholonome}</joint_name>
				<joint_name>Rouleau_c_${name_roueholonome}</joint_name>
				<joint_name>Rouleau_d_${name_roueholonome}</joint_name>
				<joint_name>Rouleau_e_${name_roueholonome}</joint_name>
				<joint_name>Rouleau_f_${name_roueholonome}</joint_name>
				<joint_name>Rouleau_g_${name_roueholonome}</joint_name>
				<joint_name>Rouleau_h_${name_roueholonome}</joint_name>
				<joint_name>Rouleau_i_${name_roueholonome}</joint_name>
				<joint_name>Rouleau_j_${name_roueholonome}</joint_name>
				<joint_name>joint_wheel_${name_roueholonome}</joint_name>
			</plugin>
		</gazebo> -->
  <gazebo>
    <plugin filename="libgazebo_ros2_control.so" name="gazebo_ros2_control">
      <robot_param>robot_description</robot_param>
      <robot_param_node>robot_state_publisher</robot_param_node>
      <parameters>/home/floris/ros2_ws/install/robot_nav/share/robot_nav/params/omnidirectional_controller.yaml</parameters>
    </plugin>
    <plugin filename="libgazebo_ros_p3d.so" name="gazebo_ros_p3d">
      <ros>
        <namespace>gazebo_ground_truth</namespace>
      </ros>
      <frame_name>world</frame_name>
      <body_name>base_link</body_name>
      <update_rate>50.0</update_rate>
      <gaussian_noise>0.01</gaussian_noise>
    </plugin>
  </gazebo>
</robot>
